Workbook

Sheet Data Sheet
A1: COMPANY NAME
A2: LATEST VERSION | F2: Do Not Make any changes to this sheet
A3: CURRENT VERSION | F3: This sheet is auto popuated by Screener
A5: META
A6: Number of shares
A7: Face Value
A8: Current Price
A9: Market Capitalization
A15: PROFIT & LOSS
A16: Report Date
A17: Sales
A18: Raw Material Cost
A19: Change in Inventory
A20: Power and Fuel
A21: Other Mfr. Exp
... A99: Stock Price

Sheet 📋 Cover
B1: DCF VALUATION MODEL v3.0 — IT / TECHNOLOGY SERVICES
B2: Indian Listed IT Companies · Screener.in + Trendlyne + CompaniesMarketCap · IT-Specific Assumptions Engine
B3: 🖥️ SECTOR: IT / TECHNOLOGY SERVICES
B4: COMPANY DETAILS
B5: Company Name
B6: Ticker
B7: Sector
B8: Valuation Date
B9: Analyst
B11: COLOR LEGEND — CRITICAL TO UNDERSTAND
B12: Blue / Light blue → Historical INPUT (paste from Screener.in)
B13: Blue / Yellow → KEY INPUT (forecast years from Trendlyne Forecaster, or your judgment)
... B19: PROJECTION METHODOLOGY — IT SERVICES SPECIFIC
B20: Revenue Growth % | D20: FY2027-28: Trendlyne Forecaster analyst consensus → FY2029-34: Linear taper from FY2028 to terminal g (5–6%) by FY2034
B21: EBITDA Margin % | D21: FY2027-28: Trendlyne analyst consensus → FY2029-34: Excel TREND function on 7 data points. IT margins are structurally stable (20–25% band).
B22: D&A / Revenue % | D22: FY2027-28: Derived as (EBITDA% − EBIT%) from Trendlyne → FY2029-34: TREND function (NOT median — IT D&A is trending up due to Ind AS 116 lease accounting)
B23: Capex % Revenue | D23: IT-SPECIFIC: Modelled as % of revenue (1.5–3%), NOT absolute ₹ taper. Capex scales with headcount. FY2027-28: Trendlyne. FY2029-34: held flat at FY2028 level.
B24: Working Capital | D24: NWC % OF REVENUE approach. Historical NWC% auto-calculated from Hist Data. FY2027-28: user inputs NWC% (default = 5Y hist avg). FY2029+: flat at FY2028 level. ΔWC = (NWC% × Revenue_N) − (NWC% × Revenue_N-1). No separate debtor/creditor day assumptions needed.
B25: Other Income | D25: IT-SPECIFIC: Modelled as Net Cash Balance × Treasury Yield %. IT majors earn ₹3,000–6,000 Cr/yr in interest income on cash pile. NOT flat carry-forward.
B27: QUICK START — 7 STEPS (IT Services)
B28: Step 1 | C28: 📊 Hist Data | D28: P&L, BS & CF auto-fill from the Screener export. Enter only blue cells (borrowings split, payables, capex) + yellow Market Cap (CompaniesMarketCap.com). Balance Sheet Check must = 0.
B29: Step 2 | C29: 🔑 Assumptions A | D29: Company name, ticker, IT sub-sector, effective tax rate (Screener 3Y avg, ~20-23%), terminal growth g (5-6%).
B30: Step 3 | C30: 🔑 Assumptions B | D30: Yellow cells: Revenue growth % + EBITDA margin % + D&A % from Trendlyne Forecaster. Purple cells auto-project.
B31: Step 4 | C31: 🔑 Assumptions C-D | D31: Capex % of Revenue (Trendlyne) and NWC % of Revenue (default = 5Y historical average).
B32: Step 5 | C32: 📐 Beta Calc | D32: Paste 3Y weekly closing prices for Nifty 50 + your stock (same dates, oldest at top). Beta auto-feeds WACC.
B33: Step 6 | C33: 🔑 Assumptions F | D33: Rf (India 10Y G-Sec), ERP (Damodaran India), Beta (auto from Beta Calc). WACC auto-calculated.
B34: Step 7 | C34: 💰 FCF & Val | D34: Enter current market price (yellow). Intrinsic value per share, upside % and verdict auto-populate.
B36: DATA SOURCES — WHERE TO GET EVERY NUMBER
B37: What You Need | C37: Source | D37: Exact Location / Instructions
B38: Historical P&L (Sales, EBITDA, D&A, Interest, PAT) | C38: Screener.in | D38: Company page → P&L tab → Copy 5 years
B39: Historical Balance Sheet (Debt, Cash, Receivables, etc.) | C39: Screener.in | D39: Company page → Balance Sheet tab → Expand rows
B40: Historical Cash Flow (CFO, Capex, FCF) | C40: Screener.in | D40: Company page → Cash Flows tab
B41: Trade Payables + Advance from Customers (deferred rev) | C41: Screener.in | D41: Balance Sheet → expand "Other Liabilities"
B42: Beta (3-year) | C42: Screener.in / Trendlyne | D42: Screener company page (shown directly) OR Trendlyne → Technicals
B43: Market Cap + Shares Outstanding (historical) | C43: CompaniesMarketCap.com | D43: Search company → Market Cap History → Annual data
B44: Revenue + EBITDA + Capex forecasts (next 2 FYs) | C44: Trendlyne Forecaster | D44: Company page → Forecaster tab → Estimates (Premium)
B45: Revenue + EBITDA forecasts (next 2 FYs) — alternative | C45: Market Screener | D45: Company → Financials → Estimates (Premium)
B46: Risk-Free Rate (10Y G-Sec yield) | C46: RBI / Investing.com | D46: investing.com → search "India 10 Year Bond Yield" → current yield
B47: Equity Risk Premium (India ERP) | C47: Damodaran (NYU) | D47: pages.stern.nyu.edu/~adamodar → Implied ERP → India
B48: Effective Tax Rate | C48: Screener.in | D48: P&L tab → Tax % row → use AVERAGE of last 3 years (IT: ~20-23%)
...

Sheet 📊 Hist Data
B1: HISTORICAL FINANCIALS — IT SERVICES | ₹ Crores | Upload to screener.in/excel/ → Export to Excel for any company → Dark green cells fill automatically
B2: 🟢 DARK GREEN = auto from Data Sheet (Screener export) | 🔵 LIGHT BLUE = manual entry (Screener BS/CF expand view) | 🟡 YELLOW = manual input (Market Cap, WACC inputs, Trendlyne forecasts)
B3: SECTION 1 — PROFIT & LOSS | 🟢 Dark Green = auto from Screener Data Sheet | 🔵 Light Blue = manual from Screener expanded view
B4: Screener Label | C4: =IFERROR("FY"&TEXT('Data Sheet'!G16,"YYYY"),"FY2022") -> FY1899 | D4: =IFERROR("FY"&TEXT('Data Sheet'!H16,"YYYY"),"FY2023") -> FY1899 | E4: =IFERROR("FY"&TEXT('Data Sheet'!I16,"YYYY"),"FY2024") -> FY1899 | F4: =IFERROR("FY"&TEXT('Data Sheet'!J16,"YYYY"),"FY2025") -> FY1899 | G4: =IFERROR("FY"&TEXT('Data Sheet'!K16,"YYYY"),"FY2026") -> FY1899 | I4: SOURCE → WHERE TO GET THIS DATA
B5: Sales | C5: =IFERROR('Data Sheet'!G17,0) -> 0 | D5: =IFERROR('Data Sheet'!H17,0) -> 0 | E5: =IFERROR('Data Sheet'!I17,0) -> 0 | F5: =IFERROR('Data Sheet'!J17,0) -> 0 | G5: =IFERROR('Data Sheet'!K17,0) -> 0 | I5: 🟢 AUTO from Data Sheet row 17 (Sales). Screener fills this when you Export to Excel.
B6: Operating Profit (EBITDA) | C6: =IFERROR('Data Sheet'!G28+'Data Sheet'!G26+'Data Sheet'!G27-'Data Sheet'!G25,0) -> 0 | D6: =IFERROR('Data Sheet'!H28+'Data Sheet'!H26+'Data Sheet'!H27-'Data Sheet'!H25,0) -> 0 | E6: =IFERROR('Data Sheet'!I28+'Data Sheet'!I26+'Data Sheet'!I27-'Data Sheet'!I25,0) -> 0 | F6: =IFERROR('Data Sheet'!J28+'Data Sheet'!J26+'Data Sheet'!J27-'Data Sheet'!J25,0) -> 0 | G6: =IFERROR('Data Sheet'!K28+'Data Sheet'!K26+'Data Sheet'!K27-'Data Sheet'!K25,0) -> 0 | I6: 🟢 AUTO: EBITDA = PBT + D&A + Interest − Other Income (all from Data Sheet). Cross-check: should match Screener Operating Profit.
B7: Other Income | C7: =IFERROR('Data Sheet'!G25,0) -> 0 | D7: =IFERROR('Data Sheet'!H25,0) -> 0 | E7: =IFERROR('Data Sheet'!I25,0) -> 0 | F7: =IFERROR('Data Sheet'!J25,0) -> 0 | G7: =IFERROR('Data Sheet'!K25,0) -> 0 | I7: 🟢 AUTO from Data Sheet row 25 (Other Income).
B8: Interest | C8: =IFERROR('Data Sheet'!G27,0) -> 0 | D8: =IFERROR('Data Sheet'!H27,0) -> 0 | E8: =IFERROR('Data Sheet'!I27,0) -> 0 | F8: =IFERROR('Data Sheet'!J27,0) -> 0 | G8: =IFERROR('Data Sheet'!K27,0) -> 0 | I8: 🟢 AUTO from Data Sheet row 27 (Interest).
B9: Depreciation (D&A) | C9: =IFERROR('Data Sheet'!G26,0) -> 0 | D9: =IFERROR('Data Sheet'!H26,0) -> 0 | E9: =IFERROR('Data Sheet'!I26,0) -> 0 | F9: =IFERROR('Data Sheet'!J26,0) -> 0 | G9: =IFERROR('Data Sheet'!K26,0) -> 0 | I9: 🟢 AUTO from Data Sheet row 26 (Depreciation).
B10: Profit Before Tax | C10: =IFERROR('Data Sheet'!G28,0) -> 0 | D10: =IFERROR('Data Sheet'!H28,0) -> 0 | E10: =IFERROR('Data Sheet'!I28,0) -> 0 | F10: =IFERROR('Data Sheet'!J28,0) -> 0 | G10: =IFERROR('Data Sheet'!K28,0) -> 0 | I10: 🟢 AUTO from Data Sheet row 28 (Profit Before Tax).
B11: Tax % (effective) | C11: =IFERROR('Data Sheet'!G29/'Data Sheet'!G28,0) -> 0 | D11: =IFERROR('Data Sheet'!H29/'Data Sheet'!H28,0) -> 0 | E11: =IFERROR('Data Sheet'!I29/'Data Sheet'!I28,0) -> 0 | F11: =IFERROR('Data Sheet'!J29/'Data Sheet'!J28,0) -> 0 | G11: =IFERROR('Data Sheet'!K29/'Data Sheet'!K28,0) -> 0 | I11: 🟢 AUTO: Tax % = Data Sheet Tax Amount ÷ PBT. This is effective tax rate (what company actually paid). IT companies: typically 20-23% due to SEZ/STPI benefits.
B12: Tax Amount (₹ Cr) | C12: =IFERROR('Data Sheet'!G29,0) -> 0 | D12: =IFERROR('Data Sheet'!H29,0) -> 0 | E12: =IFERROR('Data Sheet'!I29,0) -> 0 | F12: =IFERROR('Data Sheet'!J29,0) -> 0 | G12: =IFERROR('Data Sheet'!K29,0) -> 0
B13: Effective Tax Rate % | C13: =IFERROR(C12/C10,0) -> 0 | D13: =IFERROR(D12/D10,0) -> 0 | E13: =IFERROR(E12/E10,0) -> 0 | F13: =IFERROR(F12/F10,0) -> 0 | G13: =IFERROR(G12/G10,0) -> 0
B14: Net Profit | C14: =IFERROR('Data Sheet'!G30,0) -> 0 | D14: =IFERROR('Data Sheet'!H30,0) -> 0 | E14: =IFERROR('Data Sheet'!I30,0) -> 0 | F14: =IFERROR('Data Sheet'!J30,0) -> 0 | G14: =IFERROR('Data Sheet'!K30,0) -> 0 | I14: 🟢 AUTO from Data Sheet row 30 (Net Profit). Note: this is consolidated PAT. Small diff from PAT to equity due to minority interest.
B15: Minority Share | I15: 🔵 MANUAL: Screener BS → expand Other Liabilities → Non-controlling interest. Enter as NEGATIVE if minority is profitable (reduces equity PAT).
B16: PAT to Equity | C16: =IFERROR(C14+C15,0) -> 0 | D16: =IFERROR(D14+D15,0) -> 0 | E16: =IFERROR(E14+E15,0) -> 0 | F16: =IFERROR(F14+F15,0) -> 0 | G16: =IFERROR(G14+G15,0) -> 0
B17: Screener Label
B18: EBIT (₹ Cr) | C18: =IFERROR(C6-C9,0) -> 0 | D18: =IFERROR(D6-D9,0) -> 0 | E18: =IFERROR(E6-E9,0) -> 0 | F18: =IFERROR(F6-F9,0) -> 0 | G18: =IFERROR(G6-G9,0) -> 0
B19: EBITDA Margin % | C19: =IFERROR(C6/C5,0) -> 0 | D19: =IFERROR(D6/D5,0) -> 0 | E19: =IFERROR(E6/E5,0) -> 0 | F19: =IFERROR(F6/F5,0) -> 0 | G19: =IFERROR(G6/G5,0) -> 0 | I19: → Used in Assumptions B. IT range: 20-27%. TCS ~26%, Infosys ~23%, HCL ~20%.
B20: PAT to Equity Margin % | C20: =IFERROR(C16/C5,0) -> 0 | D20: =IFERROR(D16/D5,0) -> 0 | E20: =IFERROR(E16/E5,0) -> 0 | F20: =IFERROR(F16/F5,0) -> 0 | G20: =IFERROR(G16/G5,0) -> 0
B21: Revenue Growth % YoY | C21: "-" | D21: =IFERROR((D5-C5)/C5,0) -> 0 | E21: =IFERROR((E5-D5)/D5,0) -> 0 | F21: =IFERROR((F5-E5)/E5,0) -> 0 | G21: =IFERROR((G5-F5)/F5,0) -> 0 | I21: → Used in Assumptions B. IT avg growth: 8-15% for large caps.
B23: SECTION 2 — BALANCE SHEET | 🟢 Total BS items auto | 🔵 Borrowings breakdown + Trade Payables = manual (Screener expand)
B24: LIABILITIES
B25: Screener Label | C25: =IFERROR("FY"&TEXT('Data Sheet'!G16,"YYYY"),"FY2022") -> FY1899 | D25: =IFERROR("FY"&TEXT('Data Sheet'!H16,"YYYY"),"FY2023") -> FY1899 | E25: =IFERROR("FY"&TEXT('Data Sheet'!I16,"YYYY"),"FY2024") -> FY1899 | F25: =IFERROR("FY"&TEXT('Data Sheet'!J16,"YYYY"),"FY2025") -> FY1899 | G25: =IFERROR("FY"&TEXT('Data Sheet'!K16,"YYYY"),"FY2026") -> FY1899
B26: Equity Capital | C26: =IFERROR('Data Sheet'!G57,0) -> 0 | D26: =IFERROR('Data Sheet'!H57,0) -> 0 | E26: =IFERROR('Data Sheet'!I57,0) -> 0 | F26: =IFERROR('Data Sheet'!J57,0) -> 0 | G26: =IFERROR('Data Sheet'!K57,0) -> 0 | I26: 🟢 AUTO from Data Sheet row 57 (Equity Share Capital).
B27: Reserves | C27: =IFERROR('Data Sheet'!G58,0) -> 0 | D27: =IFERROR('Data Sheet'!H58,0) -> 0 | E27: =IFERROR('Data Sheet'!I58,0) -> 0 | F27: =IFERROR('Data Sheet'!J58,0) -> 0 | G27: =IFERROR('Data Sheet'!K58,0) -> 0 | I27: 🟢 AUTO from Data Sheet row 58 (Reserves).
B28: Total Equity | C28: =IFERROR(C26+C27,0) -> 0 | D28: =IFERROR(D26+D27,0) -> 0 | E28: =IFERROR(E26+E27,0) -> 0 | F28: =IFERROR(F26+F27,0) -> 0 | G28: =IFERROR(G26+G27,0) -> 0
B29: Borrowings (Total) | C29: =IFERROR('Data Sheet'!G59,0) -> 0 | D29: =IFERROR('Data Sheet'!H59,0) -> 0 | E29: =IFERROR('Data Sheet'!I59,0) -> 0 | F29: =IFERROR('Data Sheet'!J59,0) -> 0 | G29: =IFERROR('Data Sheet'!K59,0) -> 0 | I29: 🟢 AUTO from Data Sheet row 59 (Total Borrowings). For LT/ST/Lease breakdown below: manually enter from Screener BS expanded view.
B30: Long-Term Borrowings | I30: 🔵 MANUAL: Screener BS → expand Borrowings → Long Term Borrowings
B31: Short-Term Borrowings | I31: 🔵 MANUAL: Screener BS → expand Borrowings → Short Term Borrowings
B32: Lease Liabilities | I32: 🔵 MANUAL: Screener BS → expand Borrowings → Lease Liabilities (Ind AS 116)
B33: Non-Controlling Interest | I33: 🔵 MANUAL: Screener BS → expand Other Liab → Non-controlling int. Not in Data Sheet.
B34: Trade Payables | I34: 🔵 MANUAL: Screener BS → expand Other Liab → Trade Payables. Not in Data Sheet.
B35: Advance From Customers | I35: 🔵 MANUAL: Screener BS → expand Other Liab → Advance from Customers / Deferred Revenue.
B36: Other Liability Items | I36: 🔵 MANUAL: Screener BS → expand Other Liab → Other liability items. Not in Data Sheet.
B37: TOTAL LIABILITIES | C37: =SUM(C28:C29,C33:C36) -> 0 | D37: =SUM(D28:D29,D33:D36) -> 0 | E37: =SUM(E28:E29,E33:E36) -> 0 | F37: =SUM(F28:F29,F33:F36) -> 0 | G37: =SUM(G28:G29,G33:G36) -> 0 | I37: BS → 'Total Liabilities' — cross-check
B38: ASSETS
B39: Screener Label
B40: Fixed Assets (Net Block) | C40: =IFERROR('Data Sheet'!G62,0) -> 0 | D40: =IFERROR('Data Sheet'!H62,0) -> 0 | E40: =IFERROR('Data Sheet'!I62,0) -> 0 | F40: =IFERROR('Data Sheet'!J62,0) -> 0 | G40: =IFERROR('Data Sheet'!K62,0) -> 0 | I40: 🟢 AUTO from Data Sheet row 62 (Net Block).
B41: Capital WIP | C41: =IFERROR('Data Sheet'!G63,0) -> 0 | D41: =IFERROR('Data Sheet'!H63,0) -> 0 | E41: =IFERROR('Data Sheet'!I63,0) -> 0 | F41: =IFERROR('Data Sheet'!J63,0) -> 0 | G41: =IFERROR('Data Sheet'!K63,0) -> 0 | I41: 🟢 AUTO from Data Sheet row 63 (Capital Work in Progress).
...

Sheet 🔑 Assumptions
B1: ASSUMPTIONS — IT SERVICES DCF | Yellow = your input | Purple = auto-projected | Teal = IT-specific
B2: Col C = Hist Avg | Cols D-E = FY2027-28 [YELLOW — enter from Trendlyne Forecaster] | Cols F-K = FY2029-34 [PURPLE — auto-calculated]
B4: A. MODEL PARAMETERS
B5: Parameter | C5: Value | D5: Guidance
B6: Company Name | D6: e.g. Infosys, TCS, HCL Tech, Wipro, Tech Mahindra
B7: NSE Ticker | D7: e.g. INFY, TCS, HCLTECH, WIPRO, TECHM
B8: IT Sub-Sector | D8: Select: Pure-Play IT Services / IT+BPO / Product+Platform / Engineering Services / Diversified IT
B9: Currency / Units | D9: INR — ₹ Crores
B10: Last Historical FY | D10: e.g. FY2026
B11: MS Forecast Years | D11: FY2027, FY2028 (from Trendlyne Forecaster / Market Screener analyst consensus)
B12: Auto-Projected Years | D12: FY2029 – FY2034 (formula-driven)
B13: No. of Projection Years | D13: Fixed at 8 (2 analyst + 6 auto). Terminal Value captures FY2035→∞
B14: Terminal Growth Rate g | D14: 5–6% for India large-cap IT. Must be < WACC. IT terminal g typically 5.5% (GDP-linked)
B15: Corporate Tax Rate | D15: IT-SPECIFIC: Use EFFECTIVE rate from Screener P&L (3-yr avg). Indian IT: 20–23% (SEZ/STPI). Do NOT use 25.2%.
B16: Valuation Date | D16: Date of this valuation
B19: B. REVENUE & MARGIN ASSUMPTIONS | Yellow = enter from MarketScreener | Purple = auto-projected formula
B20: Assumption | C20: Hist Avg | D20: FY2027E | E20: FY2028E | F20: FY2029E | G20: FY2030E | H20: FY2031E | I20: FY2032E | J20: FY2033E | K20: FY2034E | R20: Method / Note
B21: Revenue Growth % | C21: =IFERROR(AVERAGE('📊 Hist Data'!D21:G21),0) -> 0 | G21: =IFERROR(F21-(F21-$C$14)/5*(1),0) -> 0 | H21: =IFERROR(G21-(G21-$C$14)/5*(2),0) -> 0 | I21: =IFERROR(H21-(H21-$C$14)/5*(3),0) -> 0 | J21: =IFERROR(I21-(I21-$C$14)/5*(4),0) -> 0 | K21: =IFERROR(J21-(J21-$C$14)/5*(5),0) -> 0 | R21: FY2027-28: Trendlyne Forecaster → Revenue Growth % estimate. IT large-cap: 8-15%. FY2029-34: Linear taper from FY2028 to terminal g.
B22: EBITDA Margin % | C22: =IFERROR(AVERAGE('📊 Hist Data'!C77:G77),0) -> 0 | F22: =IFERROR(E22+(E22-D22)*0.5,0) -> 0 | G22: =IFERROR(F22+(E22-D22)/3,0) -> 0 | H22: =IFERROR(G22+(E22-D22)/4,0) -> 0 | I22: =IFERROR(H22+(E22-D22)/5,0) -> 0 | J22: =IFERROR(I22+(E22-D22)/6,0) -> 0 | K22: =IFERROR(J22+(E22-D22)/7,0) -> 0 | R22: FY2027-28: Trendlyne EBITDA Margin estimate. IT benchmarks: TCS ~27%, Infosys ~24%, HCL ~20%. FY2029-34: TREND function extrapolation.
B23: D&A / Revenue % | C23: =IFERROR(AVERAGE('📊 Hist Data'!C78:G78),0) -> 0 | F23: =IFERROR(D23+(E23-D23)*0.5,0) -> 0 | G23: =IFERROR(F23+(E23-D23)*0.4,0) -> 0 | H23: =IFERROR(G23+(E23-D23)*0.3,0) -> 0 | I23: =IFERROR(H23+(E23-D23)*0.2,0) -> 0 | J23: =IFERROR(I23+(E23-D23)*0.1,0) -> 0 | K23: =IFERROR(J23,0) -> 0 | R23: IT-SPECIFIC: D&A trending UP (Ind AS 116 leases). FY2027-28: derive as (EBITDA% - EBIT%) from Trendlyne. FY2029-34: TREND extrapolation.
B24: EBIT Margin % (formula — auto) | C24: =IFERROR(AVERAGE('📊 Hist Data'!C80:G80),0) -> 0 | D24: =IFERROR(D22-D23,0) -> 0 | E24: =IFERROR(E22-E23,0) -> 0 | F24: =IFERROR(F22-F23,0) -> 0 | G24: =IFERROR(G22-G23,0) -> 0 | H24: =IFERROR(H22-H23,0) -> 0 | I24: =IFERROR(I22-I23,0) -> 0 | J24: =IFERROR(J22-J23,0) -> 0 | K24: =IFERROR(K22-K23,0) -> 0 | R24: Auto-calculated: EBITDA Margin% − D&A%. Do not edit.
B27: C. CAPEX ASSUMPTIONS — IT-SPECIFIC | Enter as % of Revenue (not ₹ Cr) | FY2029+ held flat
B28: Assumption | C28: Hist Avg | D28: FY2027E | E28: FY2028E | F28: FY2029E | G28: FY2030E | H28: FY2031E | I28: FY2032E | J28: FY2033E | K28: FY2034E | R28: Method / Note
B29: Capex / Revenue % ← ENTER THIS | C29: =IFERROR(AVERAGE('📊 Hist Data'!C79:G79),0) -> 0 | F29: =AVERAGE(C29:E29) -> 0 | G29: =$F$29 -> 0 | H29: =$F$29 -> 0 | I29: =$F$29 -> 0 | J29: =$F$29 -> 0 | K29: =$F$29 -> 0 | R29: IT-SPECIFIC DRIVER. Enter Capex as % of Revenue. FY2029-34: held flat at FY2028 rate. Benchmarks: TCS 1.5%, Infosys 2%, HCL 2.5%. Source: Trendlyne capex ÷ revenue estimate.
B30: Total Capex (₹ Cr) ← auto-derived | C30: =IFERROR(AVERAGE('📊 Hist Data'!C73:G73),0) -> 0 | D30: =IFERROR(D29*'📈 Projections'!D5,0) -> 0 | E30: =IFERROR(E29*'📈 Projections'!E5,0) -> 0 | F30: =IFERROR(F29*'📈 Projections'!F5,0) -> 0 | G30: =IFERROR(G29*'📈 Projections'!G5,0) -> 0 | H30: =IFERROR(H29*'📈 Projections'!H5,0) -> 0 | I30: =IFERROR(I29*'📈 Projections'!I5,0) -> 0 | J30: =IFERROR(J29*'📈 Projections'!J5,0) -> 0 | K30: =IFERROR(K29*'📈 Projections'!K5,0) -> 0 | R30: Auto-derived: Capex% × Projected Revenue. Do not edit directly.
B33: D. WORKING CAPITAL — NWC % OF REVENUE | NWC = NWC% × Revenue | ΔWC = Year N − Year N-1 | NWC% scales revenue growth automatically
B34: Metric | C34: Hist 5Y Avg | D34: FY2027E | E34: FY2028E | F34: FY2029E | G34: FY2030E | H34: FY2031E | I34: FY2032E | J34: FY2033E | K34: FY2034E | R34: Source / Notes
B35: Historical simple aveage of NWC % of Revenue | C35: =AVERAGE('📊 Hist Data'!C81:G81) -> #DIV/0! | R35: Auto from Hist Data. NWC = (Trade Rec + Inventories + Other CA) − (Trade Payables + Advance from Customers + Other CL). Watch the trend — declining NWC% = improving cash efficiency.
B36: ⭐ Projected NWC % (Weighted Average) | C36: =SUMPRODUCT(C38:$G$38,'📊 Hist Data'!C81:G81)/SUM('🔑 Assumptions'!$C$38:$G$38) -> #DIV/0! | D36: =IFERROR($C$36,0) -> 0 | E36: =IFERROR(D36,0) -> 0 | F36: =IFERROR($E$36,0) -> 0 | G36: =IFERROR($E$36,0) -> 0 | H36: =IFERROR($E$36,0) -> 0 | I36: =IFERROR($E$36,0) -> 0 | J36: =IFERROR($E$36,0) -> 0 | K36: =IFERROR($E$36,0) -> 0 | R36: FY2027-28: Enter from Trendlyne WC data OR keep at hist avg. FY2029+: AUTO — flat at FY2028 level. How to get NWC%: Screener.in → company page → scroll to "Working Capital" in ratios box → divide by Sales for that year. HCL hist avg ~9.7%, 3Y avg ~7%. WSS model uses 9.55%.
B37: Historical Years(N ----> Most recent year) | C37: FY_N-4 | D37: FY_N-3 | E37: FY_N-2 | F37: FY_N-1 | G37: FY_N
B38: Weights | C38: 1 | D38: 2 | E38: 3 | F38: 4 | G38: 5 | I38: Note: Default: 1,2,3,4,5 — increase FY_N weight to give more emphasis to most recent year
B52: F. WACC — 4 Steps | Ke = Rf + β×ERP | Kd = IntExp÷AvgDebt×(1-t) | WACC = Ke×E% + Kd×D%
B53: Component | C53: Value | D53: Formula / Source
B54: ── STEP 1: COST OF EQUITY Ke = Rf + β × ERP ──
B55: Risk-Free Rate Rf (%) | D55: 10Y G-Sec yield. Source: investing.com → search "India 10 Year Bond Yield" → current yield. OR RBI website → Government Securities. Current (May 2026): ~7.0-7.1%.
B56: Equity Risk Premium ERP (%) | D56: Damodaran India ERP. Source: pages.stern.nyu.edu/~adamodar → click "Implied ERP" → India row. Updated monthly. Current India ERP: ~7.0-7.5%.
B57: Beta — Current (β) | C57: =IFERROR('📐 Beta Calc'!C6,1) -> 1 | D57: Auto-linked from Beta Calc tab. SLOPE(stock weekly returns, Nifty50 returns) over 3Y. IT large-cap: TCS ~0.7, Infosys ~0.8, HCL ~0.9, Wipro ~0.9.
B58: Beta — At Maturity (β_m) | D58: Stable-state beta. IT large-cap: 0.8–1.0 (defensive growth). Mid-cap IT: 0.9–1.1. Use 1.0 if uncertain. Conservative for IT.
B59: Cost of Equity — Current Ke | C59: =IFERROR(C55+C57*C56,0) -> 0
B60: Cost of Equity — Maturity Ke_m | C60: =IFERROR(C55+C58*C56,0) -> 0
...

Sheet 📈 Projections
B1: PROJECTED FINANCIALS — IT SERVICES (₹ Crores) | All formulas — do not edit
B2: Col C = FY2026 actual (linked from Hist Data). Cols D-E = FY2027-28 (formula from yellow assumptions). Cols F-K = FY2029-34 (purple auto-formula). All cells are formulas — do not type here.
B3: PROJECTED P&L
B4: Line Item | C4: FY2026A | D4: FY2027E | E4: FY2028E | F4: FY2029E | G4: FY2030E | H4: FY2031E | I4: FY2032E | J4: FY2033E | K4: FY2034E
B5: Net Revenue (₹ Cr) | C5: =IFERROR('📊 Hist Data'!G5,0) -> 0 | D5: =C5*(1+D6) -> 0 | E5: =D5*(1+E6) -> 0 | F5: =E5*(1+F6) -> 0 | G5: =F5*(1+G6) -> 0 | H5: =G5*(1+H6) -> 0 | I5: =H5*(1+I6) -> 0 | J5: =I5*(1+J6) -> 0 | K5: =J5*(1+K6) -> 0
B6: Revenue Growth % | C6: =IFERROR('📊 Hist Data'!G21,0) -> 0 | D6: ='🔑 Assumptions'!D21 -> 0 | E6: ='🔑 Assumptions'!E21 -> 0 | F6: ='🔑 Assumptions'!F21 -> 0 | G6: ='🔑 Assumptions'!G21 -> 0 | H6: ='🔑 Assumptions'!H21 -> 0 | I6: ='🔑 Assumptions'!I21 -> 0 | J6: ='🔑 Assumptions'!J21 -> 0 | K6: ='🔑 Assumptions'!K21 -> 0
B7: EBITDA (₹ Cr) | C7: =IFERROR('📊 Hist Data'!G6,0) -> 0 | D7: =D5*D8 -> 0 | E7: =E5*E8 -> 0 | F7: =F5*F8 -> 0 | G7: =G5*G8 -> 0 | H7: =H5*H8 -> 0 | I7: =I5*I8 -> 0 | J7: =J5*J8 -> 0 | K7: =K5*K8 -> 0
B8: EBITDA Margin % | C8: =IFERROR('📊 Hist Data'!G77,0) -> 0 | D8: ='🔑 Assumptions'!D22 -> 0 | E8: ='🔑 Assumptions'!E22 -> 0 | F8: ='🔑 Assumptions'!F22 -> 0 | G8: ='🔑 Assumptions'!G22 -> 0 | H8: ='🔑 Assumptions'!H22 -> 0 | I8: ='🔑 Assumptions'!I22 -> 0 | J8: ='🔑 Assumptions'!J22 -> 0 | K8: ='🔑 Assumptions'!K22 -> 0
B9: Depreciation & Amortisation (₹ Cr) | C9: =IFERROR('📊 Hist Data'!G9,0) -> 0 | D9: =IFERROR(D5*'🔑 Assumptions'!D23,0) -> 0 | E9: =IFERROR(E5*'🔑 Assumptions'!E23,0) -> 0 | F9: =IFERROR(F5*'🔑 Assumptions'!F23,0) -> 0 | G9: =IFERROR(G5*'🔑 Assumptions'!G23,0) -> 0 | H9: =IFERROR(H5*'🔑 Assumptions'!H23,0) -> 0 | I9: =IFERROR(I5*'🔑 Assumptions'!I23,0) -> 0 | J9: =IFERROR(J5*'🔑 Assumptions'!J23,0) -> 0 | K9: =IFERROR(K5*'🔑 Assumptions'!K23,0) -> 0
B10: EBIT (₹ Cr) | C10: =IFERROR('📊 Hist Data'!G80*'📊 Hist Data'!G5,0) -> 0 | D10: =IFERROR(D7-D9,0) -> 0 | E10: =IFERROR(E7-E9,0) -> 0 | F10: =IFERROR(F7-F9,0) -> 0 | G10: =IFERROR(G7-G9,0) -> 0 | H10: =IFERROR(H7-H9,0) -> 0 | I10: =IFERROR(I7-I9,0) -> 0 | J10: =IFERROR(J7-J9,0) -> 0 | K10: =IFERROR(K7-K9,0) -> 0
B11: EBIT Margin % | C11: =IFERROR('📊 Hist Data'!G80,0) -> 0 | D11: =IFERROR(D10/D5,0) -> 0 | E11: =IFERROR(E10/E5,0) -> 0 | F11: =IFERROR(F10/F5,0) -> 0 | G11: =IFERROR(G10/G5,0) -> 0 | H11: =IFERROR(H10/H5,0) -> 0 | I11: =IFERROR(I10/I5,0) -> 0 | J11: =IFERROR(J10/J5,0) -> 0 | K11: =IFERROR(K10/K5,0) -> 0
B12: Interest Expense (₹ Cr) | C12: =IFERROR('📊 Hist Data'!G8,0) -> 0 | D12: =$C$12 -> 0 | E12: =$C$12 -> 0 | F12: =$C$12 -> 0 | G12: =$C$12 -> 0 | H12: =$C$12 -> 0 | I12: =$C$12 -> 0 | J12: =$C$12 -> 0 | K12: =$C$12 -> 0
B13: Other Income (₹ Cr) | C13: =IFERROR(ABS('📊 Hist Data'!G7),0) -> 0 | D13: =IFERROR(ABS(C13)*1.03,0) -> 0 | E13: =IFERROR(ABS(D13)*1.03,0) -> 0 | F13: =IFERROR(ABS(E13)*1.03,0) -> 0 | G13: =IFERROR(ABS(F13)*1.03,0) -> 0 | H13: =IFERROR(ABS(G13)*1.03,0) -> 0 | I13: =IFERROR(ABS(H13)*1.03,0) -> 0 | J13: =IFERROR(ABS(I13)*1.03,0) -> 0 | K13: =IFERROR(ABS(J13)*1.03,0) -> 0 | L13: ⚠ IT NOTE: If company has large cash pile (>₹10,000 Cr), consider modelling as: Cash Balance × Treasury Yield (Assumptions G). Currently carries forward historical Other Income with growth.
B14: PBT (₹ Cr) | C14: =IFERROR('📊 Hist Data'!G10,0) -> 0 | D14: =IFERROR(D10-D12+D13,0) -> 0 | E14: =IFERROR(E10-E12+E13,0) -> 0 | F14: =IFERROR(F10-F12+F13,0) -> 0 | G14: =IFERROR(G10-G12+G13,0) -> 0 | H14: =IFERROR(H10-H12+H13,0) -> 0 | I14: =IFERROR(I10-I12+I13,0) -> 0 | J14: =IFERROR(J10-J12+J13,0) -> 0 | K14: =IFERROR(K10-K12+K13,0) -> 0
B15: Tax Expense (₹ Cr) | C15: =IFERROR('📊 Hist Data'!G12,0) -> 0 | D15: =MAX(0,'🔑 Assumptions'!$C$15*D14) -> 0 | E15: =MAX(0,'🔑 Assumptions'!$C$15*E14) -> 0 | F15: =MAX(0,'🔑 Assumptions'!$C$15*F14) -> 0 | G15: =MAX(0,'🔑 Assumptions'!$C$15*G14) -> 0 | H15: =MAX(0,'🔑 Assumptions'!$C$15*H14) -> 0 | I15: =MAX(0,'🔑 Assumptions'!$C$15*I14) -> 0 | J15: =MAX(0,'🔑 Assumptions'!$C$15*J14) -> 0 | K15: =MAX(0,'🔑 Assumptions'!$C$15*K14) -> 0
B16: Effective Tax Rate % | C16: =IFERROR('📊 Hist Data'!G13,0) -> 0 | D16: =IFERROR(D15/D14,0) -> 0 | E16: =IFERROR(E15/E14,0) -> 0 | F16: =IFERROR(F15/F14,0) -> 0 | G16: =IFERROR(G15/G14,0) -> 0 | H16: =IFERROR(H15/H14,0) -> 0 | I16: =IFERROR(I15/I14,0) -> 0 | J16: =IFERROR(J15/J14,0) -> 0 | K16: =IFERROR(K15/K14,0) -> 0
B17: PAT (₹ Cr) | C17: =IFERROR('📊 Hist Data'!G14,0) -> 0 | D17: =IFERROR(D14-D15,0) -> 0 | E17: =IFERROR(E14-E15,0) -> 0 | F17: =IFERROR(F14-F15,0) -> 0 | G17: =IFERROR(G14-G15,0) -> 0 | H17: =IFERROR(H14-H15,0) -> 0 | I17: =IFERROR(I14-I15,0) -> 0 | J17: =IFERROR(J14-J15,0) -> 0 | K17: =IFERROR(K14-K15,0) -> 0
B18: PAT to Equity Margin % | C18: =IFERROR('📊 Hist Data'!G20,0) -> 0 | D18: =D20/D5 -> #DIV/0! | E18: =E20/E5 -> #DIV/0! | F18: =F20/F5 -> #DIV/0! | G18: =G20/G5 -> #DIV/0! | H18: =H20/H5 -> #DIV/0! | I18: =I20/I5 -> #DIV/0! | J18: =J20/J5 -> #DIV/0! | K18: =K20/K5 -> #DIV/0!
B19: Minority Interest (₹ Cr) | C19: =IFERROR(ABS('📊 Hist Data'!G15),0) -> 0 | D19: =IFERROR(C19*1.05,0) -> 0 | E19: =IFERROR(D19*1.05,0) -> 0 | F19: =IFERROR(E19*1.05,0) -> 0 | G19: =IFERROR(F19*1.05,0) -> 0 | H19: =IFERROR(G19*1.05,0) -> 0 | I19: =IFERROR(H19*1.05,0) -> 0 | J19: =IFERROR(I19*1.05,0) -> 0 | K19: =IFERROR(J19*1.05,0) -> 0
B20: PAT to Equity (₹ Cr) | C20: =IFERROR('📊 Hist Data'!G16,0) -> 0 | D20: =IFERROR(D17-D19,0) -> 0 | E20: =IFERROR(E17-E19,0) -> 0 | F20: =IFERROR(F17-F19,0) -> 0 | G20: =IFERROR(G17-G19,0) -> 0 | H20: =IFERROR(H17-H19,0) -> 0 | I20: =IFERROR(I17-I19,0) -> 0 | J20: =IFERROR(J17-J19,0) -> 0 | K20: =IFERROR(K17-K19,0) -> 0
B23: WORKING CAPITAL SCHEDULE | NWC = NWC% × Revenue | ΔWC feeds FCFF directly
B24: Line Item | C24: FY2026A | D24: FY2027E | E24: FY2028E | F24: FY2029E | G24: FY2030E | H24: FY2031E | I24: FY2032E | J24: FY2033E | K24: FY2034E
B25: Net Revenue (₹ Cr) [linked from P&L above] | C25: =C5 -> 0 | D25: =D5 -> 0 | E25: =E5 -> 0 | F25: =F5 -> 0 | G25: =G5 -> 0 | H25: =H5 -> 0 | I25: =I5 -> 0 | J25: =J5 -> 0 | K25: =K5 -> 0
B26: NWC % of Revenue [from Assumptions D] | C26: =IFERROR(('📊 Hist Data'!G44+'📊 Hist Data'!G43-'📊 Hist Data'!G34-'📊 Hist Data'!G35)/'📊 Hist Data'!G5,0) -> 0 | D26: =IFERROR('🔑 Assumptions'!D36,0) -> 0 | E26: =IFERROR('🔑 Assumptions'!E36,0) -> 0 | F26: =IFERROR('🔑 Assumptions'!F36,0) -> 0 | G26: =IFERROR('🔑 Assumptions'!G36,0) -> 0 | H26: =IFERROR('🔑 Assumptions'!H36,0) -> 0 | I26: =IFERROR('🔑 Assumptions'!I36,0) -> 0 | J26: =IFERROR('🔑 Assumptions'!J36,0) -> 0 | K26: =IFERROR('🔑 Assumptions'!K36,0) -> 0
B27: ⭐ Net Working Capital (₹ Cr) = NWC% × Revenue | C27: =IFERROR('📊 Hist Data'!G44+'📊 Hist Data'!G43-'📊 Hist Data'!G34-'📊 Hist Data'!G35,0) -> 0 | D27: =IFERROR(D26*D25,0) -> 0 | E27: =IFERROR(E26*E25,0) -> 0 | F27: =IFERROR(F26*F25,0) -> 0 | G27: =IFERROR(G26*G25,0) -> 0 | H27: =IFERROR(H26*H25,0) -> 0 | I27: =IFERROR(I26*I25,0) -> 0 | J27: =IFERROR(J26*J25,0) -> 0 | K27: =IFERROR(K26*K25,0) -> 0
B34: ⭐ ΔWC — Change in Working Capital (₹ Cr) | feeds FCFF | C34: "-" | D34: =IFERROR(D26*(D25-C25),0) -> 0 | E34: =IFERROR(E26*(E25-D25),0) -> 0 | F34: =IFERROR(F26*(F25-E25),0) -> 0 | G34: =IFERROR(G26*(G25-F25),0) -> 0 | H34: =IFERROR(H26*(H25-G25),0) -> 0 | I34: =IFERROR(I26*(I25-H25),0) -> 0 | J34: =IFERROR(J26*(J25-I25),0) -> 0 | K34: =IFERROR(K26*(K25-J25),0) -> 0 | L34: → This row feeds directly into FCF & Val Part 1 row 10. With NWC% flat, ΔWC ≈ NWC% × Revenue Growth. For HCL at 9.7% NWC% growing 7%/yr: ΔWC ≈ ~960 Cr/yr initially.

Sheet 💰 FCF & Val
B1: FREE CASH FLOW TO FIRM + DCF VALUATION — IT SERVICES (₹ Crores)
B3: PART 1 — FCFF = NOPAT + D&A − Capex − ΔWC
B4: Line Item | D4: FY2027E | E4: FY2028E | F4: FY2029E | G4: FY2030E | H4: FY2031E | I4: FY2032E | J4: FY2033E | K4: FY2034E
B5: EBIT (₹ Cr) | D5: =IFERROR('📈 Projections'!D10,0) -> 0 | E5: =IFERROR('📈 Projections'!E10,0) -> 0 | F5: =IFERROR('📈 Projections'!F10,0) -> 0 | G5: =IFERROR('📈 Projections'!G10,0) -> 0 | H5: =IFERROR('📈 Projections'!H10,0) -> 0 | I5: =IFERROR('📈 Projections'!I10,0) -> 0 | J5: =IFERROR('📈 Projections'!J10,0) -> 0 | K5: =IFERROR('📈 Projections'!K10,0) -> 0
B6: Tax on EBIT (EBIT × Tax Rate) | D6: =IFERROR(D5*'🔑 Assumptions'!$C$15,0) -> 0 | E6: =IFERROR(E5*'🔑 Assumptions'!$C$15,0) -> 0 | F6: =IFERROR(F5*'🔑 Assumptions'!$C$15,0) -> 0 | G6: =IFERROR(G5*'🔑 Assumptions'!$C$15,0) -> 0 | H6: =IFERROR(H5*'🔑 Assumptions'!$C$15,0) -> 0 | I6: =IFERROR(I5*'🔑 Assumptions'!$C$15,0) -> 0 | J6: =IFERROR(J5*'🔑 Assumptions'!$C$15,0) -> 0 | K6: =IFERROR(K5*'🔑 Assumptions'!$C$15,0) -> 0
B7: NOPAT — Net Operating Profit After Tax | D7: =IFERROR(D5-D6,0) -> 0 | E7: =IFERROR(E5-E6,0) -> 0 | F7: =IFERROR(F5-F6,0) -> 0 | G7: =IFERROR(G5-G6,0) -> 0 | H7: =IFERROR(H5-H6,0) -> 0 | I7: =IFERROR(I5-I6,0) -> 0 | J7: =IFERROR(J5-J6,0) -> 0 | K7: =IFERROR(K5-K6,0) -> 0
B8: + Depreciation & Amortisation | D8: =IFERROR('📈 Projections'!D9,0) -> 0 | E8: =IFERROR('📈 Projections'!E9,0) -> 0 | F8: =IFERROR('📈 Projections'!F9,0) -> 0 | G8: =IFERROR('📈 Projections'!G9,0) -> 0 | H8: =IFERROR('📈 Projections'!H9,0) -> 0 | I8: =IFERROR('📈 Projections'!I9,0) -> 0 | J8: =IFERROR('📈 Projections'!J9,0) -> 0 | K8: =IFERROR('📈 Projections'!K9,0) -> 0
B9: − Total Capex | D9: ='🔑 Assumptions'!D30 -> 0 | E9: ='🔑 Assumptions'!E30 -> 0 | F9: ='🔑 Assumptions'!F30 -> 0 | G9: ='🔑 Assumptions'!G30 -> 0 | H9: ='🔑 Assumptions'!H30 -> 0 | I9: ='🔑 Assumptions'!I30 -> 0 | J9: ='🔑 Assumptions'!J30 -> 0 | K9: ='🔑 Assumptions'!K30 -> 0
B10: − ΔWC (Change in Working Capital) | + ΔWC = cash used; − ΔWC = cash released | D10: =IFERROR('📈 Projections'!D34,0) -> 0 | E10: =IFERROR('📈 Projections'!E34,0) -> 0 | F10: =IFERROR('📈 Projections'!F34,0) -> 0 | G10: =IFERROR('📈 Projections'!G34,0) -> 0 | H10: =IFERROR('📈 Projections'!H34,0) -> 0 | I10: =IFERROR('📈 Projections'!I34,0) -> 0 | J10: =IFERROR('📈 Projections'!J34,0) -> 0 | K10: =IFERROR('📈 Projections'!K34,0) -> 0
B11: FREE CASH FLOW TO FIRM (FCFF) | D11: =IFERROR(D7+D8-D9-D10,0) -> 0 | E11: =IFERROR(E7+E8-E9-E10,0) -> 0 | F11: =IFERROR(F7+F8-F9-F10,0) -> 0 | G11: =IFERROR(G7+G8-G9-G10,0) -> 0 | H11: =IFERROR(H7+H8-H9-H10,0) -> 0 | I11: =IFERROR(I7+I8-I9-I10,0) -> 0 | J11: =IFERROR(J7+J8-J9-J10,0) -> 0 | K11: =IFERROR(K7+K8-K9-K10,0) -> 0
B12: FCFF Growth % | D12: "-" | E12: =IFERROR((E11-D11)/D11,0) -> 0 | F12: =IFERROR((F11-E11)/E11,0) -> 0 | G12: =IFERROR((G11-F11)/F11,0) -> 0 | H12: =IFERROR((H11-G11)/G11,0) -> 0 | I12: =IFERROR((I11-H11)/H11,0) -> 0 | J12: =IFERROR((J11-I11)/I11,0) -> 0 | K12: =IFERROR((K11-J11)/J11,0) -> 0
B14: PART 2 — DISCOUNTING PV = FCFF ÷ (1+WACC)^n
B15: Line Item | D15: FY2027E | E15: FY2028E | F15: FY2029E | G15: FY2030E | H15: FY2031E | I15: FY2032E | J15: FY2033E | K15: FY2034E
B16: Year Number | D16: 1 | E16: 2 | F16: 3 | G16: 4 | H16: 5 | I16: 6 | J16: 7 | K16: 8
B17: WACC — High Growth % | D17: ='🔑 Assumptions'!$C$75 -> 0.034 | E17: ='🔑 Assumptions'!$C$75 -> 0.034 | F17: ='🔑 Assumptions'!$C$75 -> 0.034 | G17: ='🔑 Assumptions'!$C$75 -> 0.034 | H17: ='🔑 Assumptions'!$C$75 -> 0.034 | I17: ='🔑 Assumptions'!$C$75 -> 0.034 | J17: ='🔑 Assumptions'!$C$75 -> 0.034 | K17: ='🔑 Assumptions'!$C$75 -> 0.034
B18: Discount Factor 1÷(1+WACC)^n | D18: =IFERROR(1/(1+D17)^D16,0) -> 0.96711799 | E18: =IFERROR(1/(1+E17)^E16,0) -> 0.9353172 | F18: =IFERROR(1/(1+F17)^F16,0) -> 0.90456209 | G18: =IFERROR(1/(1+G17)^G16,0) -> 0.87481827 | H18: =IFERROR(1/(1+H17)^H16,0) -> 0.84605249 | I18: =IFERROR(1/(1+I17)^I16,0) -> 0.81823258 | J18: =IFERROR(1/(1+J17)^J16,0) -> 0.79132745 | K18: =IFERROR(1/(1+K17)^K16,0) -> 0.76530701
B19: Present Value of FCFF (₹ Cr) | D19: =IFERROR(D11*D18,0) -> 0 | E19: =IFERROR(E11*E18,0) -> 0 | F19: =IFERROR(F11*F18,0) -> 0 | G19: =IFERROR(G11*G18,0) -> 0 | H19: =IFERROR(H11*H18,0) -> 0 | I19: =IFERROR(I11*I18,0) -> 0 | J19: =IFERROR(J11*J18,0) -> 0 | K19: =IFERROR(K11*K18,0) -> 0
B21: PART 3 — TERMINAL VALUE TV = FCFF(N+1) ÷ (WACC_tv − g) | Captures FY2035 → ∞
B22: FCFF in Terminal Year (FY2034) (₹ Cr) | C22: =IFERROR(K11,0) -> 0
B23: Terminal Growth Rate g (%) | C23: ='🔑 Assumptions'!$C$14 -> 0
B24: WACC — Terminal Phase (%) | C24: ='🔑 Assumptions'!C76 -> 0.03332
B25: FCFF Year N+1 (FY2035) (₹ Cr) | C25: =IFERROR(C22*(1+C23),0) -> 0
B26: TERMINAL VALUE (₹ Cr) — FY2035→∞ | C26: =IFERROR(C25/(C24-C23),0) -> 0
B27: Discount Factor (Year 8) | C27: =IFERROR(K18,0) -> 0.76530701
B28: PV of Terminal Value (₹ Cr) | C28: =IFERROR(C26*C27,0) -> 0
B30: ⚠ IT NOTE: Most large IT companies are NET CASH (Cash > Debt). If Net Debt (Debt - Cash) is NEGATIVE, the equity bridge ADDS net cash to EV. Check: if Total Debt < Cash & Equivalents, your Equity Value > Enterprise Value. This is correct.
B32: PART 4 — ENTERPRISE VALUE → EQUITY VALUE BRIDGE
B33: Sum of PV of FCFs (₹ Cr) | C33: =IFERROR(D19+E19+F19+G19+H19+I19+J19+K19,0) -> 0
B34: PV of Terminal Value (₹ Cr) | C34: =C28 -> 0
B35: ENTERPRISE VALUE (₹ Cr) | C35: =C33+C34 -> 0
B36: Net Cash / (Net Debt) [+ = net cash, − = net debt] | C36: ='🔑 Assumptions'!C89-'🔑 Assumptions'!C88 -> 0
B38: Less: Total Debt (₹ Cr) | C38: ='🔑 Assumptions'!$C$70 -> 0
B39: Less: Non-Controlling Interest (₹ Cr) | C39: ='🔑 Assumptions'!C91 -> 0
B40: Add: Cash & Equivalents (₹ Cr) | C40: ='🔑 Assumptions'!C89 -> 0
B41: Add: Investments (₹ Cr) | C41: ='🔑 Assumptions'!$C$90 -> 0
B42: DCF VALUE OF EQUITY (₹ Cr) | C42: =C35-C38-C39+C40+C41 -> 0
B44: Shares Outstanding (Crores) | C44: ='📊 Hist Data'!G69 -> 0
B45: INTRINSIC VALUE PER SHARE (₹) | C45: =C42/C44 -> #DIV/0!
B46: Current Market Price (₹) | C46: ='🔑 Assumptions'!C93 -> 0
B47: Upside / (Downside) % | C47: =(C45/C46-1) -> #DIV/0!
...

Sheet 🔬 Sensitivity
B1: SENSITIVITY ANALYSIS — IT SERVICES | Intrinsic Value Per Share (₹)
B2: Terminal Growth rate(col) | C2: ='🔑 Assumptions'!C14 -> 0 | E2: Wacc(row) | F2: ='🔑 Assumptions'!C75 -> 0.034
B3: TABLE — WACC (rows) vs Terminal Growth g (cols) | Auto-calculated | Green = IV > CMP
B4: ='💰 FCF & Val'!C45 -> #DIV/0! | C4: 0.03 | D4: 0.04 | E4: 0.05 | F4: 0.055 | G4: 0.06 | H4: 0.065 | I4: 0.07
B5: 0.095 | C5: =( SUMPRODUCT('💰 FCF & Val'!$D$11:$K$11,1/(1+$B5)^('💰 FCF & Val'!$D$16:$K$16)) + ('💰 FCF & Val'!$K$11*(1+C$4)/($B5+('🔑 Assumptions'!$C$76-'🔑 Assumptions'!$C$75)-C$4))/(1+$B5)^8 + '💰 FCF & Val'!$C$40+'💰 FCF & Val'!$C$41-'💰 FCF & Val'!$C$38-'💰 FCF & Val'!$C$39 )/'💰 FCF & Val'!$C$44 -> #DIV/0! | D5: =( SUMPRODUCT('💰 FCF & Val'!$D$11:$K$11,1/(1+$B5)^('💰 FCF & Val'!$D$16:$K$16)) + ('💰 FCF & Val'!$K$11*(1+D$4)/($B5+('🔑 Assumptions'!$C$76-'🔑 Assumptions'!$C$75)-D$4))/(1+$B5)^8 + '💰 FCF & Val'!$C$40+'💰 FCF & Val'!$C$41-'💰 FCF & Val'!$C$38-'💰 FCF & Val'!$C$39 )/'💰 FCF & Val'!$C$44 -> #DIV/0! | E5: =( SUMPRODUCT('💰 FCF & Val'!$D$11:$K$11,1/(1+$B5)^('💰 FCF & Val'!$D$16:$K$16)) + ('💰 FCF & Val'!$K$11*(1+E$4)/($B5+('🔑 Assumptions'!$C$76-'🔑 Assumptions'!$C$75)-E$4))/(1+$B5)^8 + '💰 FCF & Val'!$C$40+'💰 FCF & Val'!$C$41-'💰 FCF & Val'!$C$38-'💰 FCF & Val'!$C$39 )/'💰 FCF & Val'!$C$44 -> #DIV/0! | F5: =( SUMPRODUCT('💰 FCF & Val'!$D$11:$K$11,1/(1+$B5)^('💰 FCF & Val'!$D$16:$K$16)) + ('💰 FCF & Val'!$K$11*(1+F$4)/($B5+('🔑 Assumptions'!$C$76-'🔑 Assumptions'!$C$75)-F$4))/(1+$B5)^8 + '💰 FCF & Val'!$C$40+'💰 FCF & Val'!$C$41-'💰 FCF & Val'!$C$38-'💰 FCF & Val'!$C$39 )/'💰 FCF & Val'!$C$44 -> #DIV/0! | G5: =( SUMPRODUCT('💰 FCF & Val'!$D$11:$K$11,1/(1+$B5)^('💰 FCF & Val'!$D$16:$K$16)) + ('💰 FCF & Val'!$K$11*(1+G$4)/($B5+('🔑 Assumptions'!$C$76-'🔑 Assumptions'!$C$75)-G$4))/(1+$B5)^8 + '💰 FCF & Val'!$C$40+'💰 FCF & Val'!$C$41-'💰 FCF & Val'!$C$38-'💰 FCF & Val'!$C$39 )/'💰 FCF & Val'!$C$44 -> #DIV/0! | H5: =( SUMPRODUCT('💰 FCF & Val'!$D$11:$K$11,1/(1+$B5)^('💰 FCF & Val'!$D$16:$K$16)) + ('💰 FCF & Val'!$K$11*(1+H$4)/($B5+('🔑 Assumptions'!$C$76-'🔑 Assumptions'!$C$75)-H$4))/(1+$B5)^8 + '💰 FCF & Val'!$C$40+'💰 FCF & Val'!$C$41-'💰 FCF & Val'!$C$38-'💰 FCF & Val'!$C$39 )/'💰 FCF & Val'!$C$44 -> #DIV/0! | I5: =( SUMPRODUCT('💰 FCF & Val'!$D$11:$K$11,1/(1+$B5)^('💰 FCF & Val'!$D$16:$K$16)) + ('💰 FCF & Val'!$K$11*(1+I$4)/($B5+('🔑 Assumptions'!$C$76-'🔑 Assumptions'!$C$75)-I$4))/(1+$B5)^8 + '💰 FCF & Val'!$C$40+'💰 FCF & Val'!$C$41-'💰 FCF & Val'!$C$38-'💰 FCF & Val'!$C$39 )/'💰 FCF & Val'!$C$44 -> #DIV/0!
B6: 0.1 | C6: =( SUMPRODUCT('💰 FCF & Val'!$D$11:$K$11,1/(1+$B6)^('💰 FCF & Val'!$D$16:$K$16)) + ('💰 FCF & Val'!$K$11*(1+C$4)/($B6+('🔑 Assumptions'!$C$76-'🔑 Assumptions'!$C$75)-C$4))/(1+$B6)^8 + '💰 FCF & Val'!$C$40+'💰 FCF & Val'!$C$41-'💰 FCF & Val'!$C$38-'💰 FCF & Val'!$C$39 )/'💰 FCF & Val'!$C$44 -> #DIV/0! | D6: =( SUMPRODUCT('💰 FCF & Val'!$D$11:$K$11,1/(1+$B6)^('💰 FCF & Val'!$D$16:$K$16)) + ('💰 FCF & Val'!$K$11*(1+D$4)/($B6+('🔑 Assumptions'!$C$76-'🔑 Assumptions'!$C$75)-D$4))/(1+$B6)^8 + '💰 FCF & Val'!$C$40+'💰 FCF & Val'!$C$41-'💰 FCF & Val'!$C$38-'💰 FCF & Val'!$C$39 )/'💰 FCF & Val'!$C$44 -> #DIV/0! | E6: =( SUMPRODUCT('💰 FCF & Val'!$D$11:$K$11,1/(1+$B6)^('💰 FCF & Val'!$D$16:$K$16)) + ('💰 FCF & Val'!$K$11*(1+E$4)/($B6+('🔑 Assumptions'!$C$76-'🔑 Assumptions'!$C$75)-E$4))/(1+$B6)^8 + '💰 FCF & Val'!$C$40+'💰 FCF & Val'!$C$41-'💰 FCF & Val'!$C$38-'💰 FCF & Val'!$C$39 )/'💰 FCF & Val'!$C$44 -> #DIV/0! | F6: =( SUMPRODUCT('💰 FCF & Val'!$D$11:$K$11,1/(1+$B6)^('💰 FCF & Val'!$D$16:$K$16)) + ('💰 FCF & Val'!$K$11*(1+F$4)/($B6+('🔑 Assumptions'!$C$76-'🔑 Assumptions'!$C$75)-F$4))/(1+$B6)^8 + '💰 FCF & Val'!$C$40+'💰 FCF & Val'!$C$41-'💰 FCF & Val'!$C$38-'💰 FCF & Val'!$C$39 )/'💰 FCF & Val'!$C$44 -> #DIV/0! | G6: =( SUMPRODUCT('💰 FCF & Val'!$D$11:$K$11,1/(1+$B6)^('💰 FCF & Val'!$D$16:$K$16)) + ('💰 FCF & Val'!$K$11*(1+G$4)/($B6+('🔑 Assumptions'!$C$76-'🔑 Assumptions'!$C$75)-G$4))/(1+$B6)^8 + '💰 FCF & Val'!$C$40+'💰 FCF & Val'!$C$41-'💰 FCF & Val'!$C$38-'💰 FCF & Val'!$C$39 )/'💰 FCF & Val'!$C$44 -> #DIV/0! | H6: =( SUMPRODUCT('💰 FCF & Val'!$D$11:$K$11,1/(1+$B6)^('💰 FCF & Val'!$D$16:$K$16)) + ('💰 FCF & Val'!$K$11*(1+H$4)/($B6+('🔑 Assumptions'!$C$76-'🔑 Assumptions'!$C$75)-H$4))/(1+$B6)^8 + '💰 FCF & Val'!$C$40+'💰 FCF & Val'!$C$41-'💰 FCF & Val'!$C$38-'💰 FCF & Val'!$C$39 )/'💰 FCF & Val'!$C$44 -> #DIV/0! | I6: =( SUMPRODUCT('💰 FCF & Val'!$D$11:$K$11,1/(1+$B6)^('💰 FCF & Val'!$D$16:$K$16)) + ('💰 FCF & Val'!$K$11*(1+I$4)/($B6+('🔑 Assumptions'!$C$76-'🔑 Assumptions'!$C$75)-I$4))/(1+$B6)^8 + '💰 FCF & Val'!$C$40+'💰 FCF & Val'!$C$41-'💰 FCF & Val'!$C$38-'💰 FCF & Val'!$C$39 )/'💰 FCF & Val'!$C$44 -> #DIV/0!
B7: 0.11 | C7: =( SUMPRODUCT('💰 FCF & Val'!$D$11:$K$11,1/(1+$B7)^('💰 FCF & Val'!$D$16:$K$16)) + ('💰 FCF & Val'!$K$11*(1+C$4)/($B7+('🔑 Assumptions'!$C$76-'🔑 Assumptions'!$C$75)-C$4))/(1+$B7)^8 + '💰 FCF & Val'!$C$40+'💰 FCF & Val'!$C$41-'💰 FCF & Val'!$C$38-'💰 FCF & Val'!$C$39 )/'💰 FCF & Val'!$C$44 -> #DIV/0! | D7: =( SUMPRODUCT('💰 FCF & Val'!$D$11:$K$11,1/(1+$B7)^('💰 FCF & Val'!$D$16:$K$16)) + ('💰 FCF & Val'!$K$11*(1+D$4)/($B7+('🔑 Assumptions'!$C$76-'🔑 Assumptions'!$C$75)-D$4))/(1+$B7)^8 + '💰 FCF & Val'!$C$40+'💰 FCF & Val'!$C$41-'💰 FCF & Val'!$C$38-'💰 FCF & Val'!$C$39 )/'💰 FCF & Val'!$C$44 -> #DIV/0! | E7: =( SUMPRODUCT('💰 FCF & Val'!$D$11:$K$11,1/(1+$B7)^('💰 FCF & Val'!$D$16:$K$16)) + ('💰 FCF & Val'!$K$11*(1+E$4)/($B7+('🔑 Assumptions'!$C$76-'🔑 Assumptions'!$C$75)-E$4))/(1+$B7)^8 + '💰 FCF & Val'!$C$40+'💰 FCF & Val'!$C$41-'💰 FCF & Val'!$C$38-'💰 FCF & Val'!$C$39 )/'💰 FCF & Val'!$C$44 -> #DIV/0! | F7: =( SUMPRODUCT('💰 FCF & Val'!$D$11:$K$11,1/(1+$B7)^('💰 FCF & Val'!$D$16:$K$16)) + ('💰 FCF & Val'!$K$11*(1+F$4)/($B7+('🔑 Assumptions'!$C$76-'🔑 Assumptions'!$C$75)-F$4))/(1+$B7)^8 + '💰 FCF & Val'!$C$40+'💰 FCF & Val'!$C$41-'💰 FCF & Val'!$C$38-'💰 FCF & Val'!$C$39 )/'💰 FCF & Val'!$C$44 -> #DIV/0! | G7: =( SUMPRODUCT('💰 FCF & Val'!$D$11:$K$11,1/(1+$B7)^('💰 FCF & Val'!$D$16:$K$16)) + ('💰 FCF & Val'!$K$11*(1+G$4)/($B7+('🔑 Assumptions'!$C$76-'🔑 Assumptions'!$C$75)-G$4))/(1+$B7)^8 + '💰 FCF & Val'!$C$40+'💰 FCF & Val'!$C$41-'💰 FCF & Val'!$C$38-'💰 FCF & Val'!$C$39 )/'💰 FCF & Val'!$C$44 -> #DIV/0! | H7: =( SUMPRODUCT('💰 FCF & Val'!$D$11:$K$11,1/(1+$B7)^('💰 FCF & Val'!$D$16:$K$16)) + ('💰 FCF & Val'!$K$11*(1+H$4)/($B7+('🔑 Assumptions'!$C$76-'🔑 Assumptions'!$C$75)-H$4))/(1+$B7)^8 + '💰 FCF & Val'!$C$40+'💰 FCF & Val'!$C$41-'💰 FCF & Val'!$C$38-'💰 FCF & Val'!$C$39 )/'💰 FCF & Val'!$C$44 -> #DIV/0! | I7: =( SUMPRODUCT('💰 FCF & Val'!$D$11:$K$11,1/(1+$B7)^('💰 FCF & Val'!$D$16:$K$16)) + ('💰 FCF & Val'!$K$11*(1+I$4)/($B7+('🔑 Assumptions'!$C$76-'🔑 Assumptions'!$C$75)-I$4))/(1+$B7)^8 + '💰 FCF & Val'!$C$40+'💰 FCF & Val'!$C$41-'💰 FCF & Val'!$C$38-'💰 FCF & Val'!$C$39 )/'💰 FCF & Val'!$C$44 -> #DIV/0!
B8: 0.12 | C8: =( SUMPRODUCT('💰 FCF & Val'!$D$11:$K$11,1/(1+$B8)^('💰 FCF & Val'!$D$16:$K$16)) + ('💰 FCF & Val'!$K$11*(1+C$4)/($B8+('🔑 Assumptions'!$C$76-'🔑 Assumptions'!$C$75)-C$4))/(1+$B8)^8 + '💰 FCF & Val'!$C$40+'💰 FCF & Val'!$C$41-'💰 FCF & Val'!$C$38-'💰 FCF & Val'!$C$39 )/'💰 FCF & Val'!$C$44 -> #DIV/0! | D8: =( SUMPRODUCT('💰 FCF & Val'!$D$11:$K$11,1/(1+$B8)^('💰 FCF & Val'!$D$16:$K$16)) + ('💰 FCF & Val'!$K$11*(1+D$4)/($B8+('🔑 Assumptions'!$C$76-'🔑 Assumptions'!$C$75)-D$4))/(1+$B8)^8 + '💰 FCF & Val'!$C$40+'💰 FCF & Val'!$C$41-'💰 FCF & Val'!$C$38-'💰 FCF & Val'!$C$39 )/'💰 FCF & Val'!$C$44 -> #DIV/0! | E8: =( SUMPRODUCT('💰 FCF & Val'!$D$11:$K$11,1/(1+$B8)^('💰 FCF & Val'!$D$16:$K$16)) + ('💰 FCF & Val'!$K$11*(1+E$4)/($B8+('🔑 Assumptions'!$C$76-'🔑 Assumptions'!$C$75)-E$4))/(1+$B8)^8 + '💰 FCF & Val'!$C$40+'💰 FCF & Val'!$C$41-'💰 FCF & Val'!$C$38-'💰 FCF & Val'!$C$39 )/'💰 FCF & Val'!$C$44 -> #DIV/0! | F8: =( SUMPRODUCT('💰 FCF & Val'!$D$11:$K$11,1/(1+$B8)^('💰 FCF & Val'!$D$16:$K$16)) + ('💰 FCF & Val'!$K$11*(1+F$4)/($B8+('🔑 Assumptions'!$C$76-'🔑 Assumptions'!$C$75)-F$4))/(1+$B8)^8 + '💰 FCF & Val'!$C$40+'💰 FCF & Val'!$C$41-'💰 FCF & Val'!$C$38-'💰 FCF & Val'!$C$39 )/'💰 FCF & Val'!$C$44 -> #DIV/0! | G8: =( SUMPRODUCT('💰 FCF & Val'!$D$11:$K$11,1/(1+$B8)^('💰 FCF & Val'!$D$16:$K$16)) + ('💰 FCF & Val'!$K$11*(1+G$4)/($B8+('🔑 Assumptions'!$C$76-'🔑 Assumptions'!$C$75)-G$4))/(1+$B8)^8 + '💰 FCF & Val'!$C$40+'💰 FCF & Val'!$C$41-'💰 FCF & Val'!$C$38-'💰 FCF & Val'!$C$39 )/'💰 FCF & Val'!$C$44 -> #DIV/0! | H8: =( SUMPRODUCT('💰 FCF & Val'!$D$11:$K$11,1/(1+$B8)^('💰 FCF & Val'!$D$16:$K$16)) + ('💰 FCF & Val'!$K$11*(1+H$4)/($B8+('🔑 Assumptions'!$C$76-'🔑 Assumptions'!$C$75)-H$4))/(1+$B8)^8 + '💰 FCF & Val'!$C$40+'💰 FCF & Val'!$C$41-'💰 FCF & Val'!$C$38-'💰 FCF & Val'!$C$39 )/'💰 FCF & Val'!$C$44 -> #DIV/0! | I8: =( SUMPRODUCT('💰 FCF & Val'!$D$11:$K$11,1/(1+$B8)^('💰 FCF & Val'!$D$16:$K$16)) + ('💰 FCF & Val'!$K$11*(1+I$4)/($B8+('🔑 Assumptions'!$C$76-'🔑 Assumptions'!$C$75)-I$4))/(1+$B8)^8 + '💰 FCF & Val'!$C$40+'💰 FCF & Val'!$C$41-'💰 FCF & Val'!$C$38-'💰 FCF & Val'!$C$39 )/'💰 FCF & Val'!$C$44 -> #DIV/0!
B9: 0.125 | C9: =( SUMPRODUCT('💰 FCF & Val'!$D$11:$K$11,1/(1+$B9)^('💰 FCF & Val'!$D$16:$K$16)) + ('💰 FCF & Val'!$K$11*(1+C$4)/($B9+('🔑 Assumptions'!$C$76-'🔑 Assumptions'!$C$75)-C$4))/(1+$B9)^8 + '💰 FCF & Val'!$C$40+'💰 FCF & Val'!$C$41-'💰 FCF & Val'!$C$38-'💰 FCF & Val'!$C$39 )/'💰 FCF & Val'!$C$44 -> #DIV/0! | D9: =( SUMPRODUCT('💰 FCF & Val'!$D$11:$K$11,1/(1+$B9)^('💰 FCF & Val'!$D$16:$K$16)) + ('💰 FCF & Val'!$K$11*(1+D$4)/($B9+('🔑 Assumptions'!$C$76-'🔑 Assumptions'!$C$75)-D$4))/(1+$B9)^8 + '💰 FCF & Val'!$C$40+'💰 FCF & Val'!$C$41-'💰 FCF & Val'!$C$38-'💰 FCF & Val'!$C$39 )/'💰 FCF & Val'!$C$44 -> #DIV/0! | E9: =( SUMPRODUCT('💰 FCF & Val'!$D$11:$K$11,1/(1+$B9)^('💰 FCF & Val'!$D$16:$K$16)) + ('💰 FCF & Val'!$K$11*(1+E$4)/($B9+('🔑 Assumptions'!$C$76-'🔑 Assumptions'!$C$75)-E$4))/(1+$B9)^8 + '💰 FCF & Val'!$C$40+'💰 FCF & Val'!$C$41-'💰 FCF & Val'!$C$38-'💰 FCF & Val'!$C$39 )/'💰 FCF & Val'!$C$44 -> #DIV/0! | F9: =( SUMPRODUCT('💰 FCF & Val'!$D$11:$K$11,1/(1+$B9)^('💰 FCF & Val'!$D$16:$K$16)) + ('💰 FCF & Val'!$K$11*(1+F$4)/($B9+('🔑 Assumptions'!$C$76-'🔑 Assumptions'!$C$75)-F$4))/(1+$B9)^8 + '💰 FCF & Val'!$C$40+'💰 FCF & Val'!$C$41-'💰 FCF & Val'!$C$38-'💰 FCF & Val'!$C$39 )/'💰 FCF & Val'!$C$44 -> #DIV/0! | G9: =( SUMPRODUCT('💰 FCF & Val'!$D$11:$K$11,1/(1+$B9)^('💰 FCF & Val'!$D$16:$K$16)) + ('💰 FCF & Val'!$K$11*(1+G$4)/($B9+('🔑 Assumptions'!$C$76-'🔑 Assumptions'!$C$75)-G$4))/(1+$B9)^8 + '💰 FCF & Val'!$C$40+'💰 FCF & Val'!$C$41-'💰 FCF & Val'!$C$38-'💰 FCF & Val'!$C$39 )/'💰 FCF & Val'!$C$44 -> #DIV/0! | H9: =( SUMPRODUCT('💰 FCF & Val'!$D$11:$K$11,1/(1+$B9)^('💰 FCF & Val'!$D$16:$K$16)) + ('💰 FCF & Val'!$K$11*(1+H$4)/($B9+('🔑 Assumptions'!$C$76-'🔑 Assumptions'!$C$75)-H$4))/(1+$B9)^8 + '💰 FCF & Val'!$C$40+'💰 FCF & Val'!$C$41-'💰 FCF & Val'!$C$38-'💰 FCF & Val'!$C$39 )/'💰 FCF & Val'!$C$44 -> #DIV/0! | I9: =( SUMPRODUCT('💰 FCF & Val'!$D$11:$K$11,1/(1+$B9)^('💰 FCF & Val'!$D$16:$K$16)) + ('💰 FCF & Val'!$K$11*(1+I$4)/($B9+('🔑 Assumptions'!$C$76-'🔑 Assumptions'!$C$75)-I$4))/(1+$B9)^8 + '💰 FCF & Val'!$C$40+'💰 FCF & Val'!$C$41-'💰 FCF & Val'!$C$38-'💰 FCF & Val'!$C$39 )/'💰 FCF & Val'!$C$44 -> #DIV/0!
B10: 0.13 | C10: =( SUMPRODUCT('💰 FCF & Val'!$D$11:$K$11,1/(1+$B10)^('💰 FCF & Val'!$D$16:$K$16)) + ('💰 FCF & Val'!$K$11*(1+C$4)/($B10+('🔑 Assumptions'!$C$76-'🔑 Assumptions'!$C$75)-C$4))/(1+$B10)^8 + '💰 FCF & Val'!$C$40+'💰 FCF & Val'!$C$41-'💰 FCF & Val'!$C$38-'💰 FCF & Val'!$C$39 )/'💰 FCF & Val'!$C$44 -> #DIV/0! | D10: =( SUMPRODUCT('💰 FCF & Val'!$D$11:$K$11,1/(1+$B10)^('💰 FCF & Val'!$D$16:$K$16)) + ('💰 FCF & Val'!$K$11*(1+D$4)/($B10+('🔑 Assumptions'!$C$76-'🔑 Assumptions'!$C$75)-D$4))/(1+$B10)^8 + '💰 FCF & Val'!$C$40+'💰 FCF & Val'!$C$41-'💰 FCF & Val'!$C$38-'💰 FCF & Val'!$C$39 )/'💰 FCF & Val'!$C$44 -> #DIV/0! | E10: =( SUMPRODUCT('💰 FCF & Val'!$D$11:$K$11,1/(1+$B10)^('💰 FCF & Val'!$D$16:$K$16)) + ('💰 FCF & Val'!$K$11*(1+E$4)/($B10+('🔑 Assumptions'!$C$76-'🔑 Assumptions'!$C$75)-E$4))/(1+$B10)^8 + '💰 FCF & Val'!$C$40+'💰 FCF & Val'!$C$41-'💰 FCF & Val'!$C$38-'💰 FCF & Val'!$C$39 )/'💰 FCF & Val'!$C$44 -> #DIV/0! | F10: =( SUMPRODUCT('💰 FCF & Val'!$D$11:$K$11,1/(1+$B10)^('💰 FCF & Val'!$D$16:$K$16)) + ('💰 FCF & Val'!$K$11*(1+F$4)/($B10+('🔑 Assumptions'!$C$76-'🔑 Assumptions'!$C$75)-F$4))/(1+$B10)^8 + '💰 FCF & Val'!$C$40+'💰 FCF & Val'!$C$41-'💰 FCF & Val'!$C$38-'💰 FCF & Val'!$C$39 )/'💰 FCF & Val'!$C$44 -> #DIV/0! | G10: =( SUMPRODUCT('💰 FCF & Val'!$D$11:$K$11,1/(1+$B10)^('💰 FCF & Val'!$D$16:$K$16)) + ('💰 FCF & Val'!$K$11*(1+G$4)/($B10+('🔑 Assumptions'!$C$76-'🔑 Assumptions'!$C$75)-G$4))/(1+$B10)^8 + '💰 FCF & Val'!$C$40+'💰 FCF & Val'!$C$41-'💰 FCF & Val'!$C$38-'💰 FCF & Val'!$C$39 )/'💰 FCF & Val'!$C$44 -> #DIV/0! | H10: =( SUMPRODUCT('💰 FCF & Val'!$D$11:$K$11,1/(1+$B10)^('💰 FCF & Val'!$D$16:$K$16)) + ('💰 FCF & Val'!$K$11*(1+H$4)/($B10+('🔑 Assumptions'!$C$76-'🔑 Assumptions'!$C$75)-H$4))/(1+$B10)^8 + '💰 FCF & Val'!$C$40+'💰 FCF & Val'!$C$41-'💰 FCF & Val'!$C$38-'💰 FCF & Val'!$C$39 )/'💰 FCF & Val'!$C$44 -> #DIV/0! | I10: =( SUMPRODUCT('💰 FCF & Val'!$D$11:$K$11,1/(1+$B10)^('💰 FCF & Val'!$D$16:$K$16)) + ('💰 FCF & Val'!$K$11*(1+I$4)/($B10+('🔑 Assumptions'!$C$76-'🔑 Assumptions'!$C$75)-I$4))/(1+$B10)^8 + '💰 FCF & Val'!$C$40+'💰 FCF & Val'!$C$41-'💰 FCF & Val'!$C$38-'💰 FCF & Val'!$C$39 )/'💰 FCF & Val'!$C$44 -> #DIV/0!
B11: 0.14 | C11: =( SUMPRODUCT('💰 FCF & Val'!$D$11:$K$11,1/(1+$B11)^('💰 FCF & Val'!$D$16:$K$16)) + ('💰 FCF & Val'!$K$11*(1+C$4)/($B11+('🔑 Assumptions'!$C$76-'🔑 Assumptions'!$C$75)-C$4))/(1+$B11)^8 + '💰 FCF & Val'!$C$40+'💰 FCF & Val'!$C$41-'💰 FCF & Val'!$C$38-'💰 FCF & Val'!$C$39 )/'💰 FCF & Val'!$C$44 -> #DIV/0! | D11: =( SUMPRODUCT('💰 FCF & Val'!$D$11:$K$11,1/(1+$B11)^('💰 FCF & Val'!$D$16:$K$16)) + ('💰 FCF & Val'!$K$11*(1+D$4)/($B11+('🔑 Assumptions'!$C$76-'🔑 Assumptions'!$C$75)-D$4))/(1+$B11)^8 + '💰 FCF & Val'!$C$40+'💰 FCF & Val'!$C$41-'💰 FCF & Val'!$C$38-'💰 FCF & Val'!$C$39 )/'💰 FCF & Val'!$C$44 -> #DIV/0! | E11: =( SUMPRODUCT('💰 FCF & Val'!$D$11:$K$11,1/(1+$B11)^('💰 FCF & Val'!$D$16:$K$16)) + ('💰 FCF & Val'!$K$11*(1+E$4)/($B11+('🔑 Assumptions'!$C$76-'🔑 Assumptions'!$C$75)-E$4))/(1+$B11)^8 + '💰 FCF & Val'!$C$40+'💰 FCF & Val'!$C$41-'💰 FCF & Val'!$C$38-'💰 FCF & Val'!$C$39 )/'💰 FCF & Val'!$C$44 -> #DIV/0! | F11: =( SUMPRODUCT('💰 FCF & Val'!$D$11:$K$11,1/(1+$B11)^('💰 FCF & Val'!$D$16:$K$16)) + ('💰 FCF & Val'!$K$11*(1+F$4)/($B11+('🔑 Assumptions'!$C$76-'🔑 Assumptions'!$C$75)-F$4))/(1+$B11)^8 + '💰 FCF & Val'!$C$40+'💰 FCF & Val'!$C$41-'💰 FCF & Val'!$C$38-'💰 FCF & Val'!$C$39 )/'💰 FCF & Val'!$C$44 -> #DIV/0! | G11: =( SUMPRODUCT('💰 FCF & Val'!$D$11:$K$11,1/(1+$B11)^('💰 FCF & Val'!$D$16:$K$16)) + ('💰 FCF & Val'!$K$11*(1+G$4)/($B11+('🔑 Assumptions'!$C$76-'🔑 Assumptions'!$C$75)-G$4))/(1+$B11)^8 + '💰 FCF & Val'!$C$40+'💰 FCF & Val'!$C$41-'💰 FCF & Val'!$C$38-'💰 FCF & Val'!$C$39 )/'💰 FCF & Val'!$C$44 -> #DIV/0! | H11: =( SUMPRODUCT('💰 FCF & Val'!$D$11:$K$11,1/(1+$B11)^('💰 FCF & Val'!$D$16:$K$16)) + ('💰 FCF & Val'!$K$11*(1+H$4)/($B11+('🔑 Assumptions'!$C$76-'🔑 Assumptions'!$C$75)-H$4))/(1+$B11)^8 + '💰 FCF & Val'!$C$40+'💰 FCF & Val'!$C$41-'💰 FCF & Val'!$C$38-'💰 FCF & Val'!$C$39 )/'💰 FCF & Val'!$C$44 -> #DIV/0! | I11: =( SUMPRODUCT('💰 FCF & Val'!$D$11:$K$11,1/(1+$B11)^('💰 FCF & Val'!$D$16:$K$16)) + ('💰 FCF & Val'!$K$11*(1+I$4)/($B11+('🔑 Assumptions'!$C$76-'🔑 Assumptions'!$C$75)-I$4))/(1+$B11)^8 + '💰 FCF & Val'!$C$40+'💰 FCF & Val'!$C$41-'💰 FCF & Val'!$C$38-'💰 FCF & Val'!$C$39 )/'💰 FCF & Val'!$C$44 -> #DIV/0!
B12: 0.15 | C12: =( SUMPRODUCT('💰 FCF & Val'!$D$11:$K$11,1/(1+$B12)^('💰 FCF & Val'!$D$16:$K$16)) + ('💰 FCF & Val'!$K$11*(1+C$4)/($B12+('🔑 Assumptions'!$C$76-'🔑 Assumptions'!$C$75)-C$4))/(1+$B12)^8 + '💰 FCF & Val'!$C$40+'💰 FCF & Val'!$C$41-'💰 FCF & Val'!$C$38-'💰 FCF & Val'!$C$39 )/'💰 FCF & Val'!$C$44 -> #DIV/0! | D12: =( SUMPRODUCT('💰 FCF & Val'!$D$11:$K$11,1/(1+$B12)^('💰 FCF & Val'!$D$16:$K$16)) + ('💰 FCF & Val'!$K$11*(1+D$4)/($B12+('🔑 Assumptions'!$C$76-'🔑 Assumptions'!$C$75)-D$4))/(1+$B12)^8 + '💰 FCF & Val'!$C$40+'💰 FCF & Val'!$C$41-'💰 FCF & Val'!$C$38-'💰 FCF & Val'!$C$39 )/'💰 FCF & Val'!$C$44 -> #DIV/0! | E12: =( SUMPRODUCT('💰 FCF & Val'!$D$11:$K$11,1/(1+$B12)^('💰 FCF & Val'!$D$16:$K$16)) + ('💰 FCF & Val'!$K$11*(1+E$4)/($B12+('🔑 Assumptions'!$C$76-'🔑 Assumptions'!$C$75)-E$4))/(1+$B12)^8 + '💰 FCF & Val'!$C$40+'💰 FCF & Val'!$C$41-'💰 FCF & Val'!$C$38-'💰 FCF & Val'!$C$39 )/'💰 FCF & Val'!$C$44 -> #DIV/0! | F12: =( SUMPRODUCT('💰 FCF & Val'!$D$11:$K$11,1/(1+$B12)^('💰 FCF & Val'!$D$16:$K$16)) + ('💰 FCF & Val'!$K$11*(1+F$4)/($B12+('🔑 Assumptions'!$C$76-'🔑 Assumptions'!$C$75)-F$4))/(1+$B12)^8 + '💰 FCF & Val'!$C$40+'💰 FCF & Val'!$C$41-'💰 FCF & Val'!$C$38-'💰 FCF & Val'!$C$39 )/'💰 FCF & Val'!$C$44 -> #DIV/0! | G12: =( SUMPRODUCT('💰 FCF & Val'!$D$11:$K$11,1/(1+$B12)^('💰 FCF & Val'!$D$16:$K$16)) + ('💰 FCF & Val'!$K$11*(1+G$4)/($B12+('🔑 Assumptions'!$C$76-'🔑 Assumptions'!$C$75)-G$4))/(1+$B12)^8 + '💰 FCF & Val'!$C$40+'💰 FCF & Val'!$C$41-'💰 FCF & Val'!$C$38-'💰 FCF & Val'!$C$39 )/'💰 FCF & Val'!$C$44 -> #DIV/0! | H12: =( SUMPRODUCT('💰 FCF & Val'!$D$11:$K$11,1/(1+$B12)^('💰 FCF & Val'!$D$16:$K$16)) + ('💰 FCF & Val'!$K$11*(1+H$4)/($B12+('🔑 Assumptions'!$C$76-'🔑 Assumptions'!$C$75)-H$4))/(1+$B12)^8 + '💰 FCF & Val'!$C$40+'💰 FCF & Val'!$C$41-'💰 FCF & Val'!$C$38-'💰 FCF & Val'!$C$39 )/'💰 FCF & Val'!$C$44 -> #DIV/0! | I12: =( SUMPRODUCT('💰 FCF & Val'!$D$11:$K$11,1/(1+$B12)^('💰 FCF & Val'!$D$16:$K$16)) + ('💰 FCF & Val'!$K$11*(1+I$4)/($B12+('🔑 Assumptions'!$C$76-'🔑 Assumptions'!$C$75)-I$4))/(1+$B12)^8 + '💰 FCF & Val'!$C$40+'💰 FCF & Val'!$C$41-'💰 FCF & Val'!$C$38-'💰 FCF & Val'!$C$39 )/'💰 FCF & Val'!$C$44 -> #DIV/0!
B13: IT SECTOR WACC BENCHMARKS: Large-cap (TCS/Infy): 11–13% | Mid-cap IT: 13–15% | Small-cap IT: 15–17%
B14: TERMINAL GROWTH BENCHMARKS: Conservative: 5.0% | Base: 5.5% | Bullish: 6.0% | Note: India nominal GDP growth ~6.5-7%
B15: These cells now auto-populate via direct formulas (no Excel Data Table needed). Each cell re-discounts the fixed FCFF stream at its row WACC and rebuilds the terminal value at its (WACC, g). Green = intrinsic value above current market price.

Sheet 📐 Beta Calc
B1: BETA CALCULATION — 3-Year Weekly Price Data | IT Sector
B4: BETA OUTPUT
B5: Metric | C5: Value | G5: Note
B6: Calculated Beta (Raw) | C6: =SLOPE(F17:F172,E17:E172) -> #DIV/0! | G6: SLOPE(stock weekly returns, Nifty50 weekly returns). IT large-cap benchmarks: TCS ~0.7, Infosys ~0.8, HCL ~0.9, Wipro ~0.9, Tech M ~1.0. If Beta > 1.2 for large-cap IT, check your data.
B7: Beta Used in Model | C7: =B6 -> Calculated Beta (Raw) | G7: This cell links to Assumptions Section F. Verify before finalising.
B8: Data Points (weeks) | C8: =COUNTA(B16:B172) -> 157 | G8: Should be ~156 (3Y × 52W). Less = incomplete data.
B9: R-squared | C9: =IFERROR(RSQ(F17:F172,E17:E172),0) -> 0 | G9: R² > 0.3 typical for liquid large-caps.
B13: 📌 Steps: (1) Trendlyne.com → Company → Charts → Download weekly prices (3Y) → paste Closing Price → Col C OR investing.com → Nifty 50 → Historical → Weekly → 3 years → Download → paste Price col → Col C | (2) Same for your IT stock → Col D | (3) Same date range, same row count, oldest date at TOP | ⚠ IT stocks: expect Beta 0.6–1.0 for large-cap, 0.8–1.2 for mid-cap
B14: Date | C14: Nifty50 Price | D14: Stock Price | E14: Nifty50 Weekly Ret | F14: Stock Weekly Return
B15: 📌 Steps: (1) Trendlyne.com → Company → Charts → Download weekly prices (3Y) → paste Closing Price → Col C OR investing.com → Nifty 50 → Historical → Weekly → 3 years → Download → paste Price col → Col C | (2) Same for your IT stock → Col D | (3) Same date range, same row count, oldest date at TOP | ⚠ IT stocks: expect Beta 0.6–1.0 for large-cap, 0.8–1.2 for mid-cap
B16: 05/24/2026 | C16: 24031.7 | E16: "-" | F16: "-"
B17: 05/17/2026 | C17: 23719.3 | E17: =C17/C16-1 -> -0.012999496 | F17: =D17/D16-1 -> #DIV/0!
B18: 46300 | C18: 23643.5 | E18: =C18/C17-1 -> -0.0031957098 | F18: =D18/D17-1 -> #DIV/0!
B19: 46086 | C19: 24176.15 | E19: =C19/C18-1 -> 0.02252839 | F19: =D19/D18-1 -> #DIV/0!
B20: 04/26/2026 | C20: 23997.55 | E20: =C20/C19-1 -> -0.0073874459 | F20: =D20/D19-1 -> #DIV/0!
B21: 04/19/2026 | C21: 23897.95 | E21: =C21/C20-1 -> -0.0041504237 | F21: =D21/D20-1 -> #DIV/0!
B22: 46360 | C22: 24353.55 | E22: =C22/C21-1 -> 0.019064397 | F22: =D22/D21-1 -> #DIV/0!
B23: 46146 | C23: 24050.6 | E23: =C23/C22-1 -> -0.012439665 | F23: =D23/D22-1 -> #DIV/0!
B24: 03/29/2026 | C24: 22713.1 | E24: =C24/C23-1 -> -0.055611918 | F24: =D24/D23-1 -> #DIV/0!
B25: 03/22/2026 | C25: 22819.6 | E25: =C25/C24-1 -> 0.004688924 | F25: =D25/D24-1 -> #DIV/0!
B26: 03/15/2026 | C26: 23114.5 | E26: =C26/C25-1 -> 0.012923101 | F26: =D26/D25-1 -> #DIV/0!
B27: 46237 | C27: 23151.1 | E27: =C27/C26-1 -> 0.0015834217 | F27: =D27/D26-1 -> #DIV/0!
B28: 46025 | C28: 24450.45 | E28: =C28/C27-1 -> 0.056124763 | F28: =D28/D27-1 -> #DIV/0!
B29: 02/22/2026 | C29: 25178.65 | E29: =C29/C28-1 -> 0.029782683 | F29: =D29/D28-1 -> #DIV/0!
B30: 02/15/2026 | C30: 25571.25 | E30: =C30/C29-1 -> 0.015592575 | F30: =D30/D29-1 -> #DIV/0!
B31: 46236 | C31: 25471.1 | E31: =C31/C30-1 -> -0.0039165078 | F31: =D31/D30-1 -> #DIV/0!
B32: 46024 | C32: 25693.7 | E32: =C32/C31-1 -> 0.0087393163 | F32: =D32/D31-1 -> #DIV/0!
B33: 01/25/2026 | C33: 25320.65 | E33: =C33/C32-1 -> -0.014519123 | F33: =D33/D32-1 -> #DIV/0!
B34: 01/18/2026 | C34: 25048.65 | E34: =C34/C33-1 -> -0.01074222 | F34: =D34/D33-1 -> #DIV/0!
B35: 46327 | C35: 25694.35 | E35: =C35/C34-1 -> 0.025777836 | F35: =D35/D34-1 -> #DIV/0!
B36: 46113 | C36: 25683.3 | E36: =C36/C35-1 -> -0.00043005563 | F36: =D36/D35-1 -> #DIV/0!
B37: 12/28/2025 | C37: 26328.55 | E37: =C37/C36-1 -> 0.025123329 | F37: =D37/D36-1 -> #DIV/0!
B38: 12/21/2025 | C38: 26042.3 | E38: =C38/C37-1 -> -0.010872228 | F38: =D38/D37-1 -> #DIV/0!
B39: 12/14/2025 | C39: 25966.4 | E39: =C39/C38-1 -> -0.0029144891 | F39: =D39/D38-1 -> #DIV/0!
B40: 45850 | C40: 26046.95 | E40: =C40/C39-1 -> 0.0031020858 | F40: =D40/D39-1 -> #DIV/0!
B41: 11/30/2025 | C41: 26186.45 | E41: =C41/C40-1 -> 0.0053557134 | F41: =D41/D40-1 -> #DIV/0!
B42: 11/23/2025 | C42: 26202.95 | E42: =C42/C41-1 -> 0.00063009686 | F42: =D42/D41-1 -> #DIV/0!
B43: 11/16/2025 | C43: 26068.15 | E43: =C43/C42-1 -> -0.0051444589 | F43: =D43/D42-1 -> #DIV/0!
B44: 45911 | C44: 25910.05 | E44: =C44/C43-1 -> -0.0060648723 | F44: =D44/D43-1 -> #DIV/0!
B45: 45699 | C45: 25492.3 | E45: =C45/C44-1 -> -0.016123087 | F45: =D45/D44-1 -> #DIV/0!
...
